<?xml version="1.0"?>
<robot name="smartcar">
  <link name="base_link">
    <visual>
      <geometry>
        <box size="0.60854 0.46576 0.18159"/>
    </geometry>
    <origin rpy="0 0 0" xyz="0 0 0.0"/>
    <material name="gree">
        <color rgba="0 0 0.8 1"/>
    </material>
    </visual>
 </link>

 <link name="left_front_wheel">
    <visual>
      <geometry>
        <cylinder length="0.08912" radius="0.1375"/>
      </geometry>
      <material name="red">
        <color rgba="1 0 0 1"/>
      </material>
    </visual>
  </link>

  <joint name="left_front_wheel_joint" type="continuous">
    <axis xyz="0 0 1"/>
    <parent link="base_link"/>
    <child link="right_front_wheel"/>
    <origin rpy="1.57075 0 0" xyz="0.30427 0.27694 -0.07533"/>
    <limit effort="100" velocity="100"/>
    <joint_properties damping="0.0" friction="0.0"/>
  </joint>
 <link name="right_front_wheel">
    <visual>
      <geometry>
        <cylinder length="0.08912" radius="0.1375"/>
      </geometry>
      <material name="red">
        <color rgba="1 0 0 1"/>
      </material>
    </visual>
  </link>

  <joint name="right_front_wheel_joint" type="continuous">
    <axis xyz="0 0 1"/>
    <parent link="base_link"/>
    <child link="left_front_wheel"/>
    <origin rpy="1.57075 0 0" xyz="0.30427 -0.27694 -0.07533"/>
    <limit effort="100" velocity="100"/>
    <joint_properties damping="0.0" friction="0.0"/>
  </joint>
  <link name="right_back_wheel">
    <visual>
      <geometry>
        <cylinder length="0.08912" radius="0.1375"/>
      </geometry>
      <material name="red">
        <color rgba="1 0 0 1"/>
      </material>
    </visual>
  </link>

  <joint name="right_back_wheel_joint" type="continuous">
    <axis xyz="0 0 1"/>
    <parent link="base_link"/>
    <child link="right_back_wheel"/>
    <origin rpy="1.57075 0 0" xyz="-0.30427 -0.27694 -0.07533"/>
    <limit effort="100" velocity="100"/>
    <joint_properties damping="0.0" friction="0.0"/>
 </joint>

  <link name="left_back_wheel">
    <visual>
      <geometry>
        <cylinder length="0.08912" radius="0.1375"/>
      </geometry>
      <material name="red">
        <color rgba="1 0 0 1"/>
      </material>
    </visual>
  </link>

  <joint name="left_back_wheel_joint" type="continuous">
    <axis xyz="0 0 1"/>
    <parent link="base_link"/>
    <child link="left_back_wheel"/>
    <origin rpy="1.57075 0 0" xyz="-0.30427 0.27694 -0.07533"/>
    <limit effort="100" velocity="100"/>
    <joint_properties damping="0.0" friction="0.0"/>
  </joint>

<!--   <link name="hesai_lidar">
    <visual>
      <geometry>
        <cylinder radius="0.05" length="0.1"/>
      </geometry>
      <material name="white">
          <color rgba="1 1 1 1"/>
      </material>
    </visual>
  </link>

  <joint name="hesai_lidar" type="fixed">
    <parent link="base_link"/>
    <child link="hesai_lidar"/>
    <origin xyz="0 0 0.14745"/>
  </joint> -->
</robot>
